Workbook

Sheet Assumptions
A1: EV Charging Infrastructure - Financial Model Assumptions
A3: SOURCE: SDG&E 2026 Rate Schedule / CALeVIP / D03
E4: Output Cell (Med Lot Net 10-Year Profit)
A5: ELECTRICITY RATES (SDG&E 2026) | E5: =Model!E25-Model!E26-Model!E27 -> 2992265
A6: On-Peak Rate (4-9pm) | B6: 0.697 | C6: $/kWh
A7: Off-Peak Rate | B7: 0.467 | C7: $/kWh
A8: Super Off-Peak Rate | B8: 0.388 | C8: $/kWh
A9: Solar Generation Cost (midday) | B9: 0.08 | C9: $/kWh
A10: V2G Export Rate (SDG&E Dynamic Export) | B10: 0.45 | C10: $/kWh
A12: CHARGER SPECIFICATIONS
A13: Charger Type | B13: Level 2 Bidirectional | C13: -
A14: Charger Output | B14: 7.2 | C14: kW
A15: Average Charge Hours per Day (6am-3pm) | B15: 6 | C15: hours
A16: Average Discharge Hours per Day (4-9pm) | B16: 3 | C16: hours
A17: EV Battery Capacity (Tesla Model 3 equivalent) | B17: 75 | C17: kWh
A18: Round-trip Efficiency | B18: 0.85 | C18: %
A20: CAPITAL COSTS (per charger)
A21: Bidirectional Level 2 Charger Unit Cost | B21: 3500 | C21: $
A22: Installation Cost per Charger | B22: 3000 | C22: $
A23: Solar Canopy Cost per Space | B23: 4500 | C23: $
A24: Total Gross Cost per Charger | B24: =B21+B22+B23 -> 11000 | C24: $
A25: CALeVIP Rebate per Charger (75% up to $6000) | B25: =MIN(B24*0.75, 6000) -> 6000 | C25: $
A26: Net Cost per Charger (after rebate) | B26: =B24-B25 -> 5000 | C26: $
A28: OPERATING COSTS (annual, per charger)
A29: Maintenance Cost per Charger | B29: 200 | C29: $/year
A30: Software/Network Fee per Charger | B30: 150 | C30: $/year
A31: Total Annual OpEx per Charger | B31: =B29+B30 -> 350 | C31: $/year
A33: LOT SIZE SCENARIOS
A34: Small Lot - Number of Chargers | B34: 50 | C34: spaces
A35: Medium Lot - Number of Chargers | B35: 200 | C35: spaces
A36: Large Lot - Number of Chargers | B36: 500 | C36: spaces
A37: EV Adoption Rate (% of spaces used daily) | B37: 0.65 | C37: %
A39: PROJECT TIMELINE
A40: Analysis Period | B40: 10 | C40: years
A41: Annual Cost Escalation Rate | B41: 0.03 | C41: 3% inflation
A42: Average Days per Month | B42: =365/12 -> 30.416667
A43: SENSITIVITY ANALYSIS - Medium Lot Net 10-Year Profit
A44: =((B35*B37*B14*B15*B18*B10-B35*B37*B14*B15*B9)*365-B31*B35)*((1-(1+B41)^-B40)/B41)-B35*B26-B31*B35*B40 -> 2992265 | B44: 0.4 | C44: 0.5 | D44: 0.65 | E44: 0.75 | F44: 0.85
A45: 0.25 | B45: -871369.27 | C45: -514933.04 | D45: 19721.307 | E45: 376157.54 | F45: 732593.77
A46: 0.35 | B46: 43259.548 | C46: 628352.99 | D46: 1505993.1 | E46: 2091086.6 | F46: 2676180
...

Sheet Model
A1: EV Charging Infrastructure - Multi-Scenario Financial Model
A3: All values linked from Assumptions sheet. Change inputs there to update model.
A5: SCENARIO | B5: SMALL LOT | C5: SMALL LOT | D5: MEDIUM LOT | E5: MEDIUM LOT | F5: LARGE LOT | G5: LARGE LOT
A6: METRIC | B6: Gross | C6: Net (after rebate) | D6: Gross | E6: Net (after rebate) | F6: Gross | G6: Net (after rebate)
A7: CAPITAL COSTS
A8: Number of Chargers | B8: =Assumptions!B34 -> 50 | C8: =Assumptions!B34 -> 50 | D8: =Assumptions!B35 -> 200 | E8: =Assumptions!B35 -> 200 | F8: =Assumptions!B36 -> 500 | G8: =Assumptions!B36 -> 500
A9: Cost per Charger | B9: =Assumptions!B24 -> 11000 | C9: =Assumptions!B26 -> 5000 | D9: =Assumptions!B24 -> 11000 | E9: =Assumptions!B26 -> 5000 | F9: =Assumptions!B24 -> 11000 | G9: =Assumptions!B26 -> 5000
A10: Total Capital Cost | B10: =B8*B9 -> 550000 | C10: =C8*C9 -> 250000 | D10: =D8*D9 -> 2200000 | E10: =E8*E9 -> 1000000 | F10: =F8*F9 -> 5500000 | G10: =G8*G9 -> 2500000
A11: CALeVIP Rebate Total | B11: - | C11: =Assumptions!B25*Model!C8 -> 300000 | D11: - | E11: =Assumptions!B25*Model!E8 -> 1200000 | F11: - | G11: =Assumptions!B25*Model!G8 -> 3000000
A12: Net Capital Investment | B12: =B10 -> 550000 | C12: =C8*Assumptions!B26 -> 250000 | D12: =D10 -> 2200000 | E12: =E8*Assumptions!B26 -> 1000000 | F12: =F10 -> 5500000 | G12: =G8*Assumptions!B26 -> 2500000
A13: ANNUAL ENERGY ECONOMICS (per charger)
A14: Active EVs per Day | B14: =Assumptions!B34*Assumptions!B37 -> 32.5 | C14: =Assumptions!B34*Assumptions!B37 -> 32.5 | D14: =Assumptions!B35*Assumptions!B37 -> 130 | E14: =Assumptions!B35*Assumptions!B37 -> 130 | F14: =Assumptions!B36*Assumptions!B37 -> 325 | G14: =Assumptions!B36*Assumptions!B37 -> 325
A15: Solar Energy Stored per Day (kWh) | B15: =B14*Assumptions!$B$14*Assumptions!$B$15 -> 1404 | C15: =C14*Assumptions!$B$14*Assumptions!$B$15 -> 1404 | D15: =D14*Assumptions!$B$14*Assumptions!$B$15 -> 5616 | E15: =E14*Assumptions!$B$14*Assumptions!$B$15 -> 5616 | F15: =F14*Assumptions!$B$14*Assumptions!$B$15 -> 14040 | G15: =G14*Assumptions!$B$14*Assumptions!$B$15 -> 14040
A16: Energy Discharged per Day (kWh, after efficiency loss) | B16: =B15*Assumptions!$B$18 -> 1193.4 | C16: =C15*Assumptions!$B$18 -> 1193.4 | D16: =D15*Assumptions!$B$18 -> 4773.6 | E16: =E15*Assumptions!$B$18 -> 4773.6 | F16: =F15*Assumptions!$B$18 -> 11934 | G16: =G15*Assumptions!$B$18 -> 11934
A17: Peak Hours Discharged per Day | B17: =Assumptions!B16 -> 3 | C17: =Assumptions!B16 -> 3 | D17: =Assumptions!B16 -> 3 | E17: =Assumptions!B16 -> 3 | F17: =Assumptions!B16 -> 3 | G17: =Assumptions!B16 -> 3
A18: Revenue from V2G Export (daily) | B18: =B16*Assumptions!$B$10 -> 537.03 | C18: =C16*Assumptions!$B$10 -> 537.03 | D18: =D16*Assumptions!$B$10 -> 2148.12 | E18: =E16*Assumptions!$B$10 -> 2148.12 | F18: =F16*Assumptions!$B$10 -> 5370.3 | G18: =G16*Assumptions!$B$10 -> 5370.3
A19: Cost of Solar Charging (daily) | B19: =B15*Assumptions!$B$9 -> 112.32 | C19: =C15*Assumptions!$B$9 -> 112.32 | D19: =D15*Assumptions!$B$9 -> 449.28 | E19: =E15*Assumptions!$B$9 -> 449.28 | F19: =F15*Assumptions!$B$9 -> 1123.2 | G19: =G15*Assumptions!$B$9 -> 1123.2
A20: Net Daily Savings per Lot | B20: =B18-B19 -> 424.71 | C20: =C18-C19 -> 424.71 | D20: =D18-D19 -> 1698.84 | E20: =E18-E19 -> 1698.84 | F20: =F18-F19 -> 4247.1 | G20: =G18-G19 -> 4247.1
A21: Annual Revenue/Savings | B21: =B20*365 -> 155019.15 | C21: =C20*365 -> 155019.15 | D21: =D20*365 -> 620076.6 | E21: =E20*365 -> 620076.6 | F21: =F20*365 -> 1550191.5 | G21: =G20*365 -> 1550191.5
A22: Annual OpEx | B22: =Assumptions!B31*Assumptions!B34 -> 17500 | C22: =Assumptions!B31*Assumptions!B34 -> 17500 | D22: =Assumptions!B31*Assumptions!B35 -> 70000 | E22: =Assumptions!B31*Assumptions!B35 -> 70000 | F22: =Assumptions!B31*Assumptions!B36 -> 175000 | G22: =Assumptions!B31*Assumptions!B36 -> 175000
A23: Net Annual Benefit | B23: =B21-B22 -> 137519.15 | C23: =C21-C22 -> 137519.15 | D23: =D21-D22 -> 550076.6 | E23: =E21-E22 -> 550076.6 | F23: =F21-F22 -> 1375191.5 | G23: =G21-G22 -> 1375191.5
A24: 10-YEAR FINANCIAL SUMMARY
A25: Total 10-Year Revenue | B25: =B23*((1-(1+Assumptions!B41)^-Assumptions!B40)/Assumptions!B41) -> 1173066.2 | C25: =B23*((1-(1+Assumptions!B41)^-Assumptions!B40)/Assumptions!B41) -> 1173066.2 | D25: =D23*((1-(1+Assumptions!B41)^-Assumptions!B40)/Assumptions!B41) -> 4692265 | E25: =D23*((1-(1+Assumptions!B41)^-Assumptions!B40)/Assumptions!B41) -> 4692265 | F25: =F23*((1-(1+Assumptions!B41)^-Assumptions!B40)/Assumptions!B41) -> 11730662 | G25: =F23*((1-(1+Assumptions!B41)^-Assumptions!B40)/Assumptions!B41) -> 11730662
A26: Net Capital Investment | B26: =C12 -> 250000 | C26: =C12 -> 250000 | D26: =E12 -> 1000000 | E26: =E12 -> 1000000 | F26: =G12 -> 2500000 | G26: =G12 -> 2500000
A27: Total 10-Year OpEx | B27: =B22*Assumptions!B40 -> 175000 | C27: =B22*Assumptions!B40 -> 175000 | D27: =D22*Assumptions!B40 -> 700000 | E27: =D22*Assumptions!B40 -> 700000 | F27: =F22*Assumptions!B40 -> 1750000 | G27: =F22*Assumptions!B40 -> 1750000
A28: Net 10-Year Profit | B28: =B25-B26-B27 -> 748066.24 | C28: =C25-C26-C27 -> 748066.24 | D28: =D25-D26-D27 -> 2992265 | E28: =E25-E26-E27 -> 2992265 | F28: =F25-F26-F27 -> 7480662.4 | G28: =G25-G26-G27 -> 7480662.4
A29: Simple Payback Period (years) | B29: =B26/B23 -> 1.8179286 | C29: =C26/C23 -> 1.8179286 | D29: =D26/D23 -> 1.8179286 | E29: =E26/E23 -> 1.8179286 | F29: =F26/F23 -> 1.8179286 | G29: =G26/G23 -> 1.8179286
A30: Return on Investment | B30: =B28/B26 -> 2.992265 | C30: =C28/C26 -> 2.992265 | D30: =D28/D26 -> 2.992265 | E30: =E28/E26 -> 2.992265 | F30: =F28/F26 -> 2.992265 | G30: =G28/G26 -> 2.992265
A31: Breakeven Year | B31: =CEILING(B29,1) -> 2 | C31: =CEILING(C29,1) -> 2 | D31: =CEILING(D29,1) -> 2 | E31: =CEILING(E29,1) -> 2 | F31: =CEILING(F29,1) -> 2 | G31: =CEILING(G29,1) -> 2

Sheet Summary
A1: EV Charging Infrastructure - Financial Feasibility Analysis
A2: Center for Community Energy | California Model
A4: PURPOSE | B4: Evaluate the financial viability of solar-powered bidirecitonal EV charging structures across three lot sizes, analyzing capital costs, government incentives, energy savings, 10-year returns.
A5: DATA SOURCES | B5: SDG&E 2026 Rate Schedule, CALeVIP Incentive Program, U.S. Department of Energy, Center for Community Energy V2G Research
A7: PAYBACK PERIOD | C7: 10-YEAR ROI | E7: BREAKEVEN YEAR
A8: =Model!B29 -> 1.8179286 | C8: =Model!B30 -> 2.992265 | E8: =Model!B31 -> 2
A9: *Net of CAPeVIP rebates. Consistent across all lot sizes due to proportional scaling.
A11: SCENARIO COMPARISON (Net of Government Rebates)
A12: METRIC | B12: SMALL LOT | C12: (50 chargers) | D12: MEDIUM LOT | E12: (200 chargers) | F12: LARGE LOT | G12: (500 chargers)
A13: Net Capital Investment | B13: =Model!C12 -> 250000 | D13: =Model!E12 -> 1000000 | F13: =Model!G12 -> 2500000
A14: CALeVIP Rebates Received | B14: =Model!C11 -> 300000 | D14: =Model!E11 -> 1200000 | F14: =Model!G11 -> 3000000
A15: Annual Net Benefit | B15: =Model!C23 -> 137519.15 | D15: =Model!E23 -> 550076.6 | F15: =Model!G23 -> 1375191.5
A16: Total 10-Year Revenue | B16: =Model!C25 -> 1173066.2 | D16: =Model!E25 -> 4692265 | F16: =Model!G25 -> 11730662
A17: Total 10-Year OpEx | B17: =Model!C27 -> 175000 | D17: =Model!E27 -> 700000 | F17: =Model!G27 -> 1750000
A18: Net 10-Year Profit | B18: =Model!C28 -> 748066.24 | D18: =Model!E28 -> 2992265 | F18: =Model!G28 -> 7480662.4
A19: Simple Payback Period (years) | B19: =Model!C29 -> 1.8179286 | D19: =Model!E29 -> 1.8179286 | F19: =Model!G29 -> 1.8179286
A20: Return on Investment | B20: =Model!C30 -> 2.992265 | D20: =Model!E30 -> 2.992265 | F20: =Model!G30 -> 2.992265
A21: Break-Even Year | B21: =Model!C31 -> 2 | D21: =Model!E31 -> 2 | F21: =Model!G31 -> 2
A23: KEY TAKEAWAY
A24: All three scenarios demonstrate strong financial viability with a payback period under 2 years and a 10-year ROI of approximately 299%. The CALeVIP rebate progrm reduces upfront capital requirements by 55%, making solar bidirectional EV charging infrastructure highly attractive for commercial parking operators in Californa.
A25: Analysis based on SDG&E 2026 peak rate of 40.697/kWh and CALeVIP Level 2 rebate of up to $6000 per charger. Assumes 65% EV adoption rate and 85% round-trip charging efficiency.
A28: SENSITIVITY ANALYSIS: Medium Lot - Net 10-Year Profit
A29: EV Adoption Rate: | B29: =Assumptions!B44 -> 0.4 | C29: =Assumptions!C44 -> 0.5 | D29: =Assumptions!D44 -> 0.65 | E29: =Assumptions!E44 -> 0.75 | F29: =Assumptions!F44 -> 0.85
A30: =Assumptions!A45 -> 0.25 | B30: =Assumptions!B45 -> -871369.27 | C30: =Assumptions!C45 -> -514933.04 | D30: =Assumptions!D45 -> 19721.307 | E30: =Assumptions!E45 -> 376157.54 | F30: =Assumptions!F45 -> 732593.77
A31: =Assumptions!A46 -> 0.35 | B31: =Assumptions!B46 -> 43259.548 | C31: =Assumptions!C46 -> 628352.99 | D31: =Assumptions!D46 -> 1505993.1 | E31: =Assumptions!E46 -> 2091086.6 | F31: =Assumptions!F46 -> 2676180
A32: =Assumptions!A47 -> 0.45 | B32: =Assumptions!B47 -> 957888.37 | C32: =Assumptions!C47 -> 1771639 | D32: =Assumptions!D47 -> 2992265 | E32: =Assumptions!E47 -> 3806015.6 | F32: =Assumptions!F47 -> 4619766.3
A33: =Assumptions!A48 -> 0.55 | B33: =Assumptions!B48 -> 1872517.2 | C33: =Assumptions!C48 -> 2914925 | D33: =Assumptions!D48 -> 4478536.8 | E33: =Assumptions!E48 -> 5520944.7 | F33: =Assumptions!F48 -> 6563352.5
A34: =Assumptions!A49 -> 0.65 | B34: =Assumptions!B49 -> 2787146 | C34: =Assumptions!C49 -> 4058211.1 | D34: =Assumptions!D49 -> 5964808.6 | E34: =Assumptions!E49 -> 7235873.7 | F34: =Assumptions!F49 -> 8506938.7

Sheet NTM Forecast
A1: NTM Forecast - EV Charging Infrastructure (Medium Lot, 200 Chargers)
A2: Next 12 Months | Forecast vs. Simulated Actuals | Variance Analysis
B4: Forecast | E4: Actuals | J4: Chart Helper
A5: Month | B5: V2G Revenue | C5: Solar Cost | D5: Net Benefit | E5: Simulated Benefit | F5: Variance ($) | G5: Variance (%) | H5: Within 5%? | J5: Upper 5% | K5: Lower 5%
A6: 1 | B6: =Assumptions!$B$10*Assumptions!$B$35*Assumptions!$B$37*Assumptions!$B$14*Assumptions!$B$15*Assumptions!$B$18*Assumptions!$B$42 -> 65338.65 | C6: =Assumptions!$B$9*Assumptions!$B$35*Assumptions!$B$37*Assumptions!$B$14*Assumptions!$B$15*Assumptions!$B$42 -> 13665.6 | D6: =B6-C6 -> 51673.05 | E6: =D6*(1+0.03) -> 53223.241 | F6: =E6-D6 -> 1550.1915 | G6: =ABS(F6/D6) -> 0.03 | H6: =IF(G6<=0.05,"Yes","No") -> Yes | J6: =D6*1.05 -> 54256.702 | K6: =D6*0.95 -> 49089.397
A7: 2 | B7: =Assumptions!$B$10*Assumptions!$B$35*Assumptions!$B$37*Assumptions!$B$14*Assumptions!$B$15*Assumptions!$B$18*Assumptions!$B$42 -> 65338.65 | C7: =Assumptions!$B$9*Assumptions!$B$35*Assumptions!$B$37*Assumptions!$B$14*Assumptions!$B$15*Assumptions!$B$42 -> 13665.6 | D7: =B7-C7 -> 51673.05 | E7: =D7*(1-0.02) -> 50639.589 | F7: =E7-D7 -> -1033.461 | G7: =ABS(F7/D7) -> 0.02 | H7: =IF(G7<=0.05,"Yes","No") -> Yes | J7: =D7*1.05 -> 54256.702 | K7: =D7*0.95 -> 49089.397
A8: 3 | B8: =Assumptions!$B$10*Assumptions!$B$35*Assumptions!$B$37*Assumptions!$B$14*Assumptions!$B$15*Assumptions!$B$18*Assumptions!$B$42 -> 65338.65 | C8: =Assumptions!$B$9*Assumptions!$B$35*Assumptions!$B$37*Assumptions!$B$14*Assumptions!$B$15*Assumptions!$B$42 -> 13665.6 | D8: =B8-C8 -> 51673.05 | E8: =D8*(1+0.05) -> 54256.702 | F8: =E8-D8 -> 2583.6525 | G8: =ABS(F8/D8) -> 0.05 | H8: =IF(G8<=0.05,"Yes","No") -> No | J8: =D8*1.05 -> 54256.702 | K8: =D8*0.95 -> 49089.397
A9: 4 | B9: =Assumptions!$B$10*Assumptions!$B$35*Assumptions!$B$37*Assumptions!$B$14*Assumptions!$B$15*Assumptions!$B$18*Assumptions!$B$42 -> 65338.65 | C9: =Assumptions!$B$9*Assumptions!$B$35*Assumptions!$B$37*Assumptions!$B$14*Assumptions!$B$15*Assumptions!$B$42 -> 13665.6 | D9: =B9-C9 -> 51673.05 | E9: =D9*(1-0.01) -> 51156.319 | F9: =E9-D9 -> -516.7305 | G9: =ABS(F9/D9) -> 0.01 | H9: =IF(G9<=0.05,"Yes","No") -> Yes | J9: =D9*1.05 -> 54256.702 | K9: =D9*0.95 -> 49089.397
A10: 5 | B10: =Assumptions!$B$10*Assumptions!$B$35*Assumptions!$B$37*Assumptions!$B$14*Assumptions!$B$15*Assumptions!$B$18*Assumptions!$B$42 -> 65338.65 | C10: =Assumptions!$B$9*Assumptions!$B$35*Assumptions!$B$37*Assumptions!$B$14*Assumptions!$B$15*Assumptions!$B$42 -> 13665.6 | D10: =B10-C10 -> 51673.05 | E10: =D10*(1+0.02) -> 52706.511 | F10: =E10-D10 -> 1033.461 | G10: =ABS(F10/D10) -> 0.02 | H10: =IF(G10<=0.05,"Yes","No") -> Yes | J10: =D10*1.05 -> 54256.702 | K10: =D10*0.95 -> 49089.397
A11: 6 | B11: =Assumptions!$B$10*Assumptions!$B$35*Assumptions!$B$37*Assumptions!$B$14*Assumptions!$B$15*Assumptions!$B$18*Assumptions!$B$42 -> 65338.65 | C11: =Assumptions!$B$9*Assumptions!$B$35*Assumptions!$B$37*Assumptions!$B$14*Assumptions!$B$15*Assumptions!$B$42 -> 13665.6 | D11: =B11-C11 -> 51673.05 | E11: =D11*(1-0.03) -> 50122.858 | F11: =E11-D11 -> -1550.1915 | G11: =ABS(F11/D11) -> 0.03 | H11: =IF(G11<=0.05,"Yes","No") -> Yes | J11: =D11*1.05 -> 54256.702 | K11: =D11*0.95 -> 49089.397
A12: 7 | B12: =Assumptions!$B$10*Assumptions!$B$35*Assumptions!$B$37*Assumptions!$B$14*Assumptions!$B$15*Assumptions!$B$18*Assumptions!$B$42 -> 65338.65 | C12: =Assumptions!$B$9*Assumptions!$B$35*Assumptions!$B$37*Assumptions!$B$14*Assumptions!$B$15*Assumptions!$B$42 -> 13665.6 | D12: =B12-C12 -> 51673.05 | E12: =D12*(1+0.01) -> 52189.78 | F12: =E12-D12 -> 516.7305 | G12: =ABS(F12/D12) -> 0.01 | H12: =IF(G12<=0.05,"Yes","No") -> Yes | J12: =D12*1.05 -> 54256.702 | K12: =D12*0.95 -> 49089.397
A13: 8 | B13: =Assumptions!$B$10*Assumptions!$B$35*Assumptions!$B$37*Assumptions!$B$14*Assumptions!$B$15*Assumptions!$B$18*Assumptions!$B$42 -> 65338.65 | C13: =Assumptions!$B$9*Assumptions!$B$35*Assumptions!$B$37*Assumptions!$B$14*Assumptions!$B$15*Assumptions!$B$42 -> 13665.6 | D13: =B13-C13 -> 51673.05 | E13: =D13*(1-0.06) -> 48572.667 | F13: =E13-D13 -> -3100.383 | G13: =ABS(F13/D13) -> 0.06 | H13: =IF(G13<=0.05,"Yes","No") -> No | J13: =D13*1.05 -> 54256.702 | K13: =D13*0.95 -> 49089.397
A14: 9 | B14: =Assumptions!$B$10*Assumptions!$B$35*Assumptions!$B$37*Assumptions!$B$14*Assumptions!$B$15*Assumptions!$B$18*Assumptions!$B$42 -> 65338.65 | C14: =Assumptions!$B$9*Assumptions!$B$35*Assumptions!$B$37*Assumptions!$B$14*Assumptions!$B$15*Assumptions!$B$42 -> 13665.6 | D14: =B14-C14 -> 51673.05 | E14: =D14*(1+0.02) -> 52706.511 | F14: =E14-D14 -> 1033.461 | G14: =ABS(F14/D14) -> 0.02 | H14: =IF(G14<=0.05,"Yes","No") -> Yes | J14: =D14*1.05 -> 54256.702 | K14: =D14*0.95 -> 49089.397
A15: 10 | B15: =Assumptions!$B$10*Assumptions!$B$35*Assumptions!$B$37*Assumptions!$B$14*Assumptions!$B$15*Assumptions!$B$18*Assumptions!$B$42 -> 65338.65 | C15: =Assumptions!$B$9*Assumptions!$B$35*Assumptions!$B$37*Assumptions!$B$14*Assumptions!$B$15*Assumptions!$B$42 -> 13665.6 | D15: =B15-C15 -> 51673.05 | E15: =D15*(1-0.01) -> 51156.319 | F15: =E15-D15 -> -516.7305 | G15: =ABS(F15/D15) -> 0.01 | H15: =IF(G15<=0.05,"Yes","No") -> Yes | J15: =D15*1.05 -> 54256.702 | K15: =D15*0.95 -> 49089.397
A16: 11 | B16: =Assumptions!$B$10*Assumptions!$B$35*Assumptions!$B$37*Assumptions!$B$14*Assumptions!$B$15*Assumptions!$B$18*Assumptions!$B$42 -> 65338.65 | C16: =Assumptions!$B$9*Assumptions!$B$35*Assumptions!$B$37*Assumptions!$B$14*Assumptions!$B$15*Assumptions!$B$42 -> 13665.6 | D16: =B16-C16 -> 51673.05 | E16: =D16*(1+0.03) -> 53223.241 | F16: =E16-D16 -> 1550.1915 | G16: =ABS(F16/D16) -> 0.03 | H16: =IF(G16<=0.05,"Yes","No") -> Yes | J16: =D16*1.05 -> 54256.702 | K16: =D16*0.95 -> 49089.397
A17: 12 | B17: =Assumptions!$B$10*Assumptions!$B$35*Assumptions!$B$37*Assumptions!$B$14*Assumptions!$B$15*Assumptions!$B$18*Assumptions!$B$42 -> 65338.65 | C17: =Assumptions!$B$9*Assumptions!$B$35*Assumptions!$B$37*Assumptions!$B$14*Assumptions!$B$15*Assumptions!$B$42 -> 13665.6 | D17: =B17-C17 -> 51673.05 | E17: =D17*(1-0.02) -> 50639.589 | F17: =E17-D17 -> -1033.461 | G17: =ABS(F17/D17) -> 0.02 | H17: =IF(G17<=0.05,"Yes","No") -> Yes | J17: =D17*1.05 -> 54256.702 | K17: =D17*0.95 -> 49089.397
A19: NTM SUMMARY
A20: Total Forecasted Annual Benefit | C20: =SUM(D6:D17) -> 620076.6
A21: Total Simulated Actual Benefit | C21: =SUM(E6:E17) -> 620593.33
A22: Total Annual Variance ($) | C22: =SUM(B6:B17) -> 784063.8
A23: Average Monthly Variance (%) | C23: =AVERAGE(G6:G17) -> 0.025833333
A24: Max Monthly Variance (%) | C24: =MAX(G6:G17) -> 0.06
A25: All Months Within 5%? | C25: =IF(MAX(G6:G17)<=0.05,"Yes — NTM variance target met","No — variance exceeded 5%") -> No — variance exceeded 5%

Sheet PBI Scenario Summary
A1: Scenario | B1: Chargers | C1: Net Capital ($) | D1: CALeVIP Rebate ($) | E1: Annual Net Benefit ($) | F1: 10-Yr Revenue ($) | G1: 10-Yr OpEx ($) | H1: 10-Yr Profit ($) | I1: Payback (yrs) | J1: ROI (%)
A2: Small Lot | B2: 50 | C2: 250000 | D2: 300000 | E2: 137519 | F2: 1173066 | G2: 175000 | H2: 748066 | I2: 1.8 | J2: 2.992
A3: Medium Lot | B3: 200 | C3: 1000000 | D3: 1200000 | E3: 550077 | F3: 4692265 | G3: 700000 | H3: 2992265 | I3: 1.8 | J3: 2.992
A4: Large Lot | B4: 500 | C4: 2500000 | D4: 3000000 | E4: 1375192 | F4: 11730662 | G4: 1750000 | H4: 7480662 | I4: 1.8 | J4: 2.992

Sheet PBI Assumptions
A1: Assumption | B1: Value | C1: Unit
A2: On-Peak Electricity Rate | B2: 0.697 | C2: $/kWh
A3: V2G Export Rate | B3: 0.45 | C3: $/kWh
A4: Solar Generation Cost | B4: 0.08 | C4: $/kWh
A5: EV Adoption Rate | B5: 0.65 | C5: %
A6: Round-trip Efficiency | B6: 0.85 | C6: %
A7: CALeVIP Rebate per Charger | B7: 6000 | C7: $
A8: Net Cost per Charger | B8: 5000 | C8: $
A9: Annual OpEx per Charger | B9: 350 | C9: $/yr
A10: Analysis Period | B10: 10 | C10: years
A11: Annual Escalation Rate | B11: 0.03 | C11: %

Sheet PBI NTM Forecast
A1: Month | B1: Forecasted V2G Revenue ($) | C1: Forecasted Solar Cost ($) | D1: Forecasted Net Benefit ($) | E1: Simulated Actual ($) | F1: Variance ($) | G1: Variance (%) | H1: Within 5%?
A2: 1 | B2: 65339 | C2: 13666 | D2: 51673 | E2: 53223 | F2: 1550 | G2: 0.03 | H2: Yes
A3: 2 | B3: 65339 | C3: 13666 | D3: 51673 | E3: 50640 | F3: -1033 | G3: 0.02 | H3: Yes
A4: 3 | B4: 65339 | C4: 13666 | D4: 51673 | E4: 54257 | F4: 2584 | G4: 0.05 | H4: No
A5: 4 | B5: 65339 | C5: 13666 | D5: 51673 | E5: 51156 | F5: -517 | G5: 0.01 | H5: Yes
A6: 5 | B6: 65339 | C6: 13666 | D6: 51673 | E6: 52707 | F6: 1033 | G6: 0.02 | H6: Yes
A7: 6 | B7: 65339 | C7: 13666 | D7: 51673 | E7: 50123 | F7: -1550 | G7: 0.03 | H7: Yes
A8: 7 | B8: 65339 | C8: 13666 | D8: 51673 | E8: 52190 | F8: 517 | G8: 0.01 | H8: Yes
A9: 8 | B9: 65339 | C9: 13666 | D9: 51673 | E9: 48573 | F9: -3100 | G9: 0.06 | H9: No
A10: 9 | B10: 65339 | C10: 13666 | D10: 51673 | E10: 52707 | F10: 1033 | G10: 0.02 | H10: Yes
A11: 10 | B11: 65339 | C11: 13666 | D11: 51673 | E11: 51156 | F11: -517 | G11: 0.01 | H11: Yes
A12: 11 | B12: 65339 | C12: 13666 | D12: 51673 | E12: 53223 | F12: 1550 | G12: 0.03 | H12: Yes
